Workbook

Sheet ccdh orden
B1: M 440-460 | C1: M 460-490 | D1: M 490+ | E1: C 440-460 | F1: C 460-490 | G1: C 490+ | H1: Overo Negro | I1: Ternero Mestizo INVERNADA (160 - 180 kg) | J1: Ternera Cruza (160 - 180 g) | K1: Indice NOV | L1: Indice Ternero Campo | M1: Vaca Corte (vaca Unión Europea) | N1: Vaca Manuf | O1: Vaca Conserva
A2: 45660 | B2: 4000 | C2: 4400 | D2: 4400 | E2: 3900 | F2: 4200 | G2: 4200 | H2: 3900 | I2: 3200 | J2: 2700 | K2: 4142.5 | L2: 2750 | M2: 3800 | N2: 3200 | O2: 2900
A3: 45667 | B3: 4000 | C3: 4400 | D3: 4400 | E3: 3900 | F3: 4200 | G3: 4200 | H3: 3900 | I3: 3200 | J3: 2900 | K3: 4142.5 | L3: 2887.5 | M3: 3200 | N3: 2900 | O3: 3100
A4: 45674 | B4: 4200 | C4: 4400 | D4: 4400 | E4: 4000 | F4: 4100 | G4: 4100 | H4: 4000 | I4: 3200 | J4: 2900 | K4: 4245 | L4: 2887.5 | M4: 3800 | N4: 3200 | O4: 2900
A5: 45681 | B5: 4400 | C5: 4500 | D5: 4500 | E5: 4150 | F5: 4400 | G5: 4400 | H5: 4000 | I5: 3200 | J5: 2900 | K5: 4365 | L5: 2887.5 | M5: 3800 | N5: 3300 | O5: 3300
A6: 45688 | B6: 4700 | C6: 4600 | D6: 4600 | E6: 4400 | F6: 4500 | G6: 4500 | H6: 4200 | I6: 3300 | J6: 2900 | K6: 4595 | L6: 2975 | M6: 3900 | N6: 3300 | O6: 3000
A7: 45695 | B7: 4900 | C7: 4800 | D7: 4800 | E7: 4400 | F7: 4700 | G7: 4700 | H7: 4400 | I7: 3300 | J7: 2900 | K7: 4725 | L7: 2975 | M7: 3900 | N7: 3200 | O7: 3100
A8: 45702 | B8: 4900 | C8: 5000 | D8: 5000 | E8: 4600 | F8: 5000 | G8: 5000 | H8: 4700 | I8: 3400 | J8: 3100 | K8: 4918 | L8: 3088 | M8: 4000 | N8: 3250 | O8: 3150
A9: 45709 | B9: 4950 | C9: 5000 | D9: 5000 | E9: 4700 | F9: 4900 | G9: 4900 | H9: 4700 | I9: 3400 | J9: 3100 | K9: 4915 | L9: 3087.5 | M9: 4000 | N9: 3100 | O9: 2900
A10: 45716 | B10: 5100 | C10: 5100 | D10: 5100 | E10: 4850 | F10: 5000 | G10: 5000 | H10: 4800 | I10: 3500 | J10: 3200 | K10: 5005 | L10: 3150 | M10: 4000 | N10: 3100 | O10: 2900
A11: 45723 | B11: 5000 | C11: 5100 | D11: 5100 | E11: 4850 | F11: 5000 | G11: 5000 | H11: 4600 | I11: 3500 | J11: 3200 | K11: 4997.5 | L11: 3150 | M11: 4000 | N11: 3100 | O11: 2900
A12: 45730 | B12: 5200 | C12: 5100 | D12: 5100 | E12: 5000 | F12: 5000 | G12: 5000 | H12: 4800 | I12: 3600 | J12: 3200 | K12: 5160 | L12: 3250 | M12: 4100 | N12: 3300 | O12: 3000
A13: 45737 | B13: 5300 | C13: 5200 | D13: 5200 | E13: 5100 | F13: 5100 | G13: 5100 | H13: 4800 | I13: 3600 | J13: 3200 | K13: 5210 | L13: 3250 | M13: 4100 | N13: 3300 | O13: 2900
... A80: 46206 | B80: 7900 | C80: 8000 | D80: 8000 | E80: 7500 | F80: 7700 | G80: 7700 | H80: 7300 | I80: 6600 | J80: 6200 | K80: 7860 | L80: 6162.5 | M80: 6500 | N80: 5500 | O80: 5100

Sheet MDO AGROGANADERO
E1: PIE EN PESOS | L1: PIE EN DÓLARES
B2: Novillito -300/390 (-350) | C2: Vaquillona -350 (270-390)* | D2: Vaca c/cría usada (Julio) | E2: Novillito 391/430 | F2: NOVILLOS 431/460 | G2: NOVILLOS 461/490 | H2: NOVILLOS 491/520 | I2: NOVILLOS + 520 | K2: TC | L2: Novillito 391/430 | M2: NOVILLOS 431/460 | N2: NOVILLOS 461/490 | O2: NOVILLOS 491/520 | P2: NOVILLOS + 520
A3: 45660 | B3: 2590.05 | C3: 2408.62 | D3: 540000 | E3: 2451.04 | F3: 2330.61 | G3: 2429.07 | H3: 2326.08 | I3: 2161.09
A4: 45667 | B4: 2460.16 | C4: 2364.23 | D4: 550000 | E4: 2381.87 | F4: 2313.54 | G4: 2293.24 | H4: 2271.74 | I4: 2127.39
A5: 45674 | B5: 2528.51 | C5: 2453.06 | D5: 520000 | E5: 2356.47 | F5: 2310.01 | G5: 2359.34 | H5: 2283.59 | I5: 2168.97
A6: 45681 | B6: 2638.72 | C6: 2558.96 | D6: 480000 | E6: 2501.39 | F6: 2429.52 | G6: 2338.24 | H6: 2433.04 | I6: 2262.66
A7: 45688 | B7: 2724.02 | C7: 2652.26 | D7: 500000 | E7: 2584.78 | F7: 2512.81 | G7: 2527.89 | H7: 2557.27 | I7: 2333.19
A8: 45695 | B8: 2880.61 | C8: 2788.75 | D8: 550000 | E8: 2738.8 | F8: 2646.6 | G8: 2669.71 | H8: 2595.51 | I8: 2454.97
A9: 45702 | D9: 500000
A10: 45709 | D10: 500000
A11: 45716 | D11: 520000
A12: 45723 | D12: 520000
A13: 45730 | D13: 580000
A14: 45737 | D14: 520000
A15: 45744 | D15: 550000
A16: 45751 | D16: 600000
A17: 45758 | D17: 580000
A18: 45765 | D18: 580000
A19: 45772 | D19: 580000
A20: 45779 | D20: 600000
... A50: 45989 | D50: 1000000
A51: 45996 | B51: 4378 | D51: 1100000
A52: 46003 | B52: 4342 | D52: 1150000
A53: 46010 | B53: 4248 | D53: 1150000
A54: 46017 | D54: 1110000
A55: 46024 | B55: =4444 -> 4444 | C55: =4429 -> 4429 | D55: 900000 | E55: 4427 | F55: 4258 | G55: 4390 | H55: 4011 | I55: 3933 | K55: 1469.61 | L55: =+E55/K55 -> 3.0123638 | M55: =+F55/K55 -> 2.8973673 | N55: =+G55/K55 -> 2.9871871 | O55: =+H55/K55 -> 2.7292955 | P55: =+I55/K55 -> 2.6762202
A56: 46031 | B56: =4457 -> 4457 | C56: =4270 -> 4270 | D56: 900000 | E56: 4294 | F56: 4274 | G56: 4282 | H56: 4183 | I56: 4213 | K56: 1466.4689 | L56: =+E56/K56 -> 2.9281221 | M56: =+F56/K56 -> 2.9144839 | N56: =+G56/K56 -> 2.9199392 | O56: =+H56/K56 -> 2.8524301 | P56: =+I56/K56 -> 2.8728874
A57: 46038 | B57: =4395 -> 4395 | C57: =4260 -> 4260 | D57: 1000000 | E57: 4253 | F57: 4273 | G57: 4287 | H57: 4364 | I57: 3915 | K57: 1431.055 | L57: =+E57/K57 -> 2.9719333 | M57: =+F57/K57 -> 2.985909 | N57: =+G57/K57 -> 2.995692 | O57: =+H57/K57 -> 3.0494984 | P57: =+I57/K57 -> 2.7357439
A58: 46045 | B58: =4414 -> 4414 | C58: =4307 -> 4307 | D58: 1000000 | E58: 4348 | F58: 4251 | G58: 4253 | H58: 4228 | I58: 3989 | K58: 1433.1999 | L58: =+E58/K58 -> 3.0337708 | M58: =+F58/K58 -> 2.9660901 | N58: =+G58/K58 -> 2.9674856 | O58: =+H58/K58 -> 2.9500421 | P58: =+I58/K58 -> 2.7832824
A59: 46052 | B59: =4581 -> 4581 | C59: =4361 -> 4361 | D59: 950000 | E59: 4440 | F59: 4293 | G59: 4336 | H59: 4589 | I59: 4334 | K59: 1447.6657 | L59: =+E59/K59 -> 3.0670064 | M59: =+F59/K59 -> 2.9654636 | N59: =+G59/K59 -> 2.9951666 | O59: =+H59/K59 -> 3.1699307 | P59: =+I59/K59 -> 2.9937851
A60: 46059 | B60: =4698 -> 4698 | C60: =4545 -> 4545 | D60: 950000 | E60: 4593 | F60: 4388 | G60: 4491 | H60: 4530 | I60: 4246 | K60: 1430.589 | L60: =+E60/K60 -> 3.2105657 | M60: =+F60/K60 -> 3.0672681 | N60: =+G60/K60 -> 3.1392664 | O60: =+H60/K60 -> 3.1665279 | P60: =+I60/K60 -> 2.9680083
A61: 46066 | B61: =4696 -> 4696 | C61: =4772 -> 4772 | D61: 1200000 | E61: 4754 | F61: 4638 | G61: 4661 | H61: 4590 | I61: 4438 | K61: 1395.4205 | L61: =+E61/K61 -> 3.4068584 | M61: =+F61/K61 -> 3.3237293 | N61: =+G61/K61 -> 3.3402118 | O61: =+H61/K61 -> 3.2893311 | P61: =+I61/K61 -> 3.1804033
A62: 46073 | B62: =5089 -> 5089 | C62: =4958 -> 4958 | D62: 1200000 | E62: 4773 | F62: 4723 | G62: 4713 | H62: 4677 | I62: 4664 | K62: 1384.205 | L62: =+E62/K62 -> 3.4481887 | M62: =+F62/K62 -> 3.4120669 | N62: =+G62/K62 -> 3.4048425 | O62: =+H62/K62 -> 3.3788348 | P62: =+I62/K62 -> 3.3694431
A63: 46080 | B63: =5203 -> 5203 | C63: =5085 -> 5085 | D63: 1200000 | E63: 5055 | F63: 4750 | G63: 4762 | H63: 4739 | I63: 4451 | K63: 1408.9662 | L63: =+E63/K63 -> 3.5877369 | M63: =+F63/K63 -> 3.3712661 | N63: =+G63/K63 -> 3.379783 | O63: =+H63/K63 -> 3.363459 | P63: =+I63/K63 -> 3.1590538
A64: 46087 | B64: =4847.9 -> 4847.9 | C64: =5047 -> 5047 | D64: 1150000 | E64: 4848 | F64: 4670 | G64: 4683 | H64: 4556 | I64: 4426 | K64: 1413.8218 | L64: =+E64/K64 -> 3.4290036 | M64: =+F64/K64 -> 3.3031037 | N64: =+G64/K64 -> 3.3122986 | O64: =+H64/K64 -> 3.2224712 | P64: =+I64/K64 -> 3.1305218
A65: 46094 | B65: =4709 -> 4709 | C65: =4914 -> 4914 | D65: 1200000 | E65: 4709 | F65: 4699 | G65: 4608 | H65: 4606 | I65: 4189 | K65: 1392.98 | L65: =+E65/K65 -> 3.3805223 | M65: =+F65/K65 -> 3.3733435 | N65: =+G65/K65 -> 3.3080159 | O65: =+H65/K65 -> 3.3065801 | P65: =+I65/K65 -> 3.0072219
A66: 46101 | B66: =4649 -> 4649 | C66: =4798 -> 4798 | D66: 1100000 | E66: 4649 | F66: 4620 | G66: 4694 | H66: 4569 | I66: 3968 | K66: 1393.44 | L66: =+E66/K66 -> 3.3363475 | M66: =+F66/K66 -> 3.3155357 | N66: =+G66/K66 -> 3.3686416 | O66: =+H66/K66 -> 3.2789356 | P66: =+I66/K66 -> 2.8476289
A67: 46108 | B67: =4572 -> 4572 | C67: =4756 -> 4756 | D67: 1100000 | E67: 4572 | F67: 4542 | G67: 4429 | H67: 4386 | I67: 4250 | K67: 1376 | L67: =+E67/K67 -> 3.3226744 | M67: =+F67/K67 -> 3.3008721 | N67: =+G67/K67 -> 3.21875 | O67: =+H67/K67 -> 3.1875 | P67: =+I67/K67 -> 3.0886628
A68: 46115 | B68: =4929 -> 4929 | C68: =4639 -> 4639 | D68: 1100000 | E68: 4539 | F68: 4399 | G68: 4335 | H68: 4280 | I68: 4078 | K68: 1387.7 | L68: =+E68/K68 -> 3.2708799 | M68: =+F68/K68 -> 3.1699935 | N68: =+G68/K68 -> 3.123874 | O68: =+H68/K68 -> 3.0842401 | P68: =+I68/K68 -> 2.9386755
A69: 46122 | B69: =4959 -> 4959 | C69: =4852 -> 4852 | D69: 1000000 | E69: 4575 | F69: 4450 | G69: 4408 | H69: 4324 | I69: 4134 | K69: 1373.9 | L69: =+E69/K69 -> 3.3299367 | M69: =+F69/K69 -> 3.2389548 | N69: =+G69/K69 -> 3.2083849 | O69: =+H69/K69 -> 3.1472451 | P69: =+I69/K69 -> 3.0089526
...

Sheet PROMEDIOS
B1: PIE EN PESOS | J1: PIE EN DÓLARES
B2: Novillo Exp. | C2: Ternero AA | D2: Ternera Cruza | E2: Vaca con cría | F2: Consumo liviano | G2: Vaca Manuf | H2: Vaca Conserva | J2: Novillito 391/430 | K2: NOVILLOS 431/460 | L2: NOVILLOS 461/490 | M2: NOVILLOS 491/520 | N2: NOVILLOS + 520
A3: 46023 | B3: =AVERAGE('ccdh orden'!B54:H58)*0.585 -> 4382.4857 | C3: =AVERAGE('ccdh orden'!I54:I58) -> 5760 | D3: =AVERAGE('ccdh orden'!J54:J58) -> 4880 | E3: =AVERAGE('MDO AGROGANADERO'!D55:D59) -> 950000 | F3: =AVERAGE('MDO AGROGANADERO'!B55:C59) -> 4391.8 | G3: =AVERAGE('ccdh orden'!N54:N58)*0.5 -> 2750 | H3: =AVERAGE('ccdh orden'!O54:O58)*0.46 -> 2382.8 | J3: =AVERAGE('MDO AGROGANADERO'!L55:L59) -> 3.0026393 | K3: =AVERAGE('MDO AGROGANADERO'!M55:M59) -> 2.9458628 | L3: =AVERAGE('MDO AGROGANADERO'!N55:N59) -> 2.9730941 | M3: =AVERAGE('MDO AGROGANADERO'!O55:O59) -> 2.9502394 | N3: =AVERAGE('MDO AGROGANADERO'!P55:P59) -> 2.8123838
A4: 46054 | B4: =AVERAGE('ccdh orden'!B59:H62)*0.585 -> 4690.4464 | C4: =AVERAGE('ccdh orden'!I59:I62) -> 6050 | D4: =AVERAGE('ccdh orden'!J59:J62) -> 5450 | E4: =AVERAGE('MDO AGROGANADERO'!D60:D63) -> 1137500 | F4: =AVERAGE('MDO AGROGANADERO'!B60:C63) -> 4880.75 | G4: =AVERAGE('ccdh orden'!N59:N62)*0.5 -> 2800 | H4: =AVERAGE('ccdh orden'!O59:O62)*0.46 -> 2461 | J4: =AVERAGE('MDO AGROGANADERO'!L60:L63) -> 3.4133374 | K4: =AVERAGE('MDO AGROGANADERO'!M60:M63) -> 3.2935826 | L4: =AVERAGE('MDO AGROGANADERO'!N60:N63) -> 3.3160259 | M4: =AVERAGE('MDO AGROGANADERO'!O60:O63) -> 3.2995382 | N4: =AVERAGE('MDO AGROGANADERO'!P60:P63) -> 3.1692271
A5: 46082 | B5: =AVERAGE('ccdh orden'!B63:H66)*0.585 -> 4759.3929 | C5: =AVERAGE('ccdh orden'!I63:I66) -> 6750 | D5: =AVERAGE('ccdh orden'!J67:J70) -> 6150 | E5: =AVERAGE('MDO AGROGANADERO'!D64:D67) -> 1137500 | F5: =AVERAGE('MDO AGROGANADERO'!B68:C71) -> 4851.5 | G5: =AVERAGE('ccdh orden'!N63:N66)*0.5 -> 2925 | H5: =AVERAGE('ccdh orden'!O63:O66)*0.46 -> 2633.5 | J5: =AVERAGE('MDO AGROGANADERO'!L64:L67) -> 3.3671369 | K5: =AVERAGE('MDO AGROGANADERO'!M64:M67) -> 3.3232137 | L5: =AVERAGE('MDO AGROGANADERO'!N64:N67) -> 3.3019265 | M5: =AVERAGE('MDO AGROGANADERO'!O64:O67) -> 3.2488717 | N5: =AVERAGE('MDO AGROGANADERO'!P64:P67) -> 3.0185089
A6: 46113 | B6: =AVERAGE('ccdh orden'!B67:H70)*0.585 -> 4717.6071 | C6: =AVERAGE('ccdh orden'!I67:I70) -> 6650 | D6: =AVERAGE('ccdh orden'!J64:J67) -> 6000 | E6: =AVERAGE('MDO AGROGANADERO'!D68:D71) -> 1025000 | F6: =AVERAGE('MDO AGROGANADERO'!B65:C68) -> 4745.75 | G6: =AVERAGE('ccdh orden'!N67:N70)*0.5 -> 2900 | H6: =AVERAGE('ccdh orden'!O67:O70)*0.46 -> 2564.5 | J6: =AVERAGE('MDO AGROGANADERO'!L68:L71) -> 3.340834 | K6: =AVERAGE('MDO AGROGANADERO'!M68:M71) -> 3.2106259 | L6: =AVERAGE('MDO AGROGANADERO'!N68:N71) -> 3.1714997 | M6: =AVERAGE('MDO AGROGANADERO'!O68:O71) -> 3.1533011 | N6: =AVERAGE('MDO AGROGANADERO'!P68:P71) -> 3.0076125
A7: 46143 | J7: =AVERAGE('MDO AGROGANADERO'!L72:L76) -> 3.2636613 | K7: =AVERAGE('MDO AGROGANADERO'!M72:M76) -> 3.1924198 | L7: =AVERAGE('MDO AGROGANADERO'!N72:N76) -> 3.1412297 | M7: =AVERAGE('MDO AGROGANADERO'!O72:O76) -> 3.1012161 | N7: =AVERAGE('MDO AGROGANADERO'!P72:P76) -> 2.9656303
A8: 46174 | J8: =AVERAGE('MDO AGROGANADERO'!L77:L80) -> 3.1081562 | K8: =AVERAGE('MDO AGROGANADERO'!M77:M80) -> 2.9947293 | L8: =AVERAGE('MDO AGROGANADERO'!N77:N80) -> 2.9577936 | M8: =AVERAGE('MDO AGROGANADERO'!O77:O80) -> 2.8812291 | N8: =AVERAGE('MDO AGROGANADERO'!P77:P80) -> 2.7985454
A9: 46204
A10: 46235
A11: 46266
A22: Variación quincenal
A23: variacion mensual
A24: variación anual
